<?xml version="1.0" ?>
<robot name="hinged_drawer">
    <link name="top_left_table">
        <contact>
            <lateral_friction value="0.5"/>
        </contact>
        <inertial>
            <origin rpy="0 0 0" xyz="0.945 0.1 1.26"/>
            <mass value="0.0"/>
            <inertia ixx="0.000758" ixy="-0.000002" ixz="0.000002" iyy="0.001665" iyz="-0.000003" izz="0.001678"/>
        </inertial>
        <visual>
            <origin rpy="0 0 0" xyz="0 0 0"/>
            <geometry>
            <mesh filename="../meshes/top_left_shelf.obj" scale="1.0 1.0 1.0"/>
            </geometry>
            <material name="white">
            <color rgba="1 1 1 1"/>
            </material>
        </visual>
        <collision>
            <origin rpy="0 0 0" xyz="0 0 0"/>
            <geometry>
            <mesh filename="../meshes/top_left_shelf_vhacd2.obj" scale="1.0 1.0 1.0"/>
            </geometry>
        </collision>
    </link>

    <joint name="top_left_door_joint" type="revolute">
        <origin rpy="0 0 0" xyz="1.26 0.23 1.26"/>
        <parent link="top_left_table"/>
        <child link="leftTopDoor"/>
        <dynamics damping="1.0" friction="0.5"/>
        <limit effort="100" lower="0.0" upper="1.75" velocity="0.1"/>
        <axis xyz="0 0 -1"/>
    </joint>

    <link name="leftTopDoor">
        <contact>
            <lateral_friction value="0.5"/>
        </contact>
        <inertial>
            <origin rpy="0 0 0" xyz="-0.34 0.03 0"/>
            <mass value="1.0"/>
            <inertia ixx="0.000006" ixy="0.000000" ixz="-0.000000" iyy="0.000029" iyz="0.000000" izz="0.000024"/>
        </inertial>
        <visual>
            <origin rpy="0 0 0" xyz="-1.26 -0.23 -1.26"/>
            <geometry>
            <mesh filename="../meshes/top_left_door_round_big_handle.obj" scale="1.0 1.0 1.0"/>
            </geometry>
            <material name="white">
            <color rgba="1 1 1 1"/>
            </material>
        </visual>
        <collision>
            <origin rpy="0 0 0" xyz="-1.26 -0.22 -1.26"/>
            <geometry>
            <mesh filename="../meshes/top_left_door_round_big_handle_vhacd2.obj" scale="1.0 1.0 1.0"/>
            </geometry>
        </collision>
    </link>

    <!-- Dummy Links -->
    <joint name="leftTopDoor__topDoorHandle" type="fixed">
        <origin rpy="0 0 0" xyz="-0.565 0.07 0.0"/>
        <parent link="leftTopDoor"/>
        <child link="topDoorHandle"/>
    </joint>

    <link name="topDoorHandle">
        <inertial>
            <origin rpy="0 0 0" xyz="0 0 0"/>
            <mass value="0"/>
            <inertia ixx="1" ixy="0" ixz="0" iyy="1" iyz="0" izz="1"/>
        </inertial>
    </link>
</robot>
